<?xml version="1.0"?>
<robot name="scara">

    <material name="blue">
        <color rgba="0 0 0.8 1"/>
    </material>

    <material name="green">
        <color rgba="0 0.8 0 1"/>
    </material>

    <link name = "base_link">
        <visual>
            <geometry>
                <cylinder length="0.02" radius="0.2"/>
            </geometry>
        </visual>
    </link>

    <joint name="base_to_link1" type="fixed">
        <parent link="base_link"/>
        <child link="link1"/>
        <origin xyz="0 0 0.01"/>
    </joint>

    <link name="link1">
        <visual>
            <geometry>
                <box size="0.4 0.25 0.25"/>
            </geometry>
            <origin rpy="0 1.57 0" xyz="0 0 0.2" />
            <material name="blue"/>
        </visual>
    </link>

    <joint name="link1_to_link2" type="revolute">
        <limit lower="-2.5" upper="2.5" effort="1.0" velocity="1.0"/>
        <axis xyz="0 0 1"/>
        <parent link="link1"/>
        <child link="link2"/>
        <origin xyz="0 0 0.4"/>
    </joint>

    <link name="link2">
        <visual>
            <geometry>
                <box size="0.3 0.2 0.2"/>
            </geometry>
            <origin rpy="0 0 0" xyz="0.15 0 0.1" />
            <material name="green"/>
        </visual>
    </link>

    <joint name="link2_to_link3" type="revolute">
        <limit lower="-2" upper="2" effort="1.0" velocity="1.0"/>
        <axis xyz="0 0 1"/>
        <parent link="link2"/>
        <child link="link3"/>
        <origin xyz="0.3 0 0"/>
    </joint>

    <link name="link3">
        <visual>
            <geometry>
                <box size="0.3 0.15 0.15"/>
            </geometry>
            <origin rpy="0 0 0" xyz="0.15 0 0.075" />
            <material name="blue"/>
        </visual>
    </link>

    <joint name="link3_to_link4A" type="prismatic">
        <limit lower="0" upper="0.45" effort="1.0" velocity="1.0"/>
        <axis xyz="0 0 1"/>
        <parent link="link3"/>
        <child link="link4A"/>
        <origin rpy="3.14 0 0" xyz="0.3 0 0"/>
    </joint>

    <link name="link4A"/>

    <joint name="link4A_to_link4B" type="revolute">
        <limit lower="-3" upper="3" effort="1.0" velocity="1.0"/>
        <axis xyz="0 0 1"/>
        <parent link="link4A"/>
        <child link="link4B"/>
        <origin rpy="3.14 0 0" xyz="0 0 0"/>
    </joint>

    <link name="link4B">
        <visual>
            <geometry>
                <cylinder length="0.5" radius="0.05"/>
            </geometry>
            <origin rpy="0 0 0" xyz="0 0 0.25" />
            <material name="green"/>
        </visual>
    </link>


</robot>